<?xml version="1.0"?>
<robot xmlns:xacro="http://www.ros.org/wiki/xacro" name="leader">

  <xacro:macro name="inertial_sphere" params="mass radius *origin">
    <inertial>
      <xacro:insert_block name="origin"/>
      <mass value="${mass}" />
      <inertia ixx="${(2/5) * mass * (radius*radius)}" ixy="0.0" ixz="0.0"
               iyy="${(2/5) * mass * (radius*radius)}" iyz="0.0"
               izz="${(2/5) * mass * (radius*radius)}" />
    </inertial>
  </xacro:macro>

  <xacro:macro name="inertial_box" params="mass x y z *origin">
    <inertial>
      <xacro:insert_block name="origin"/>
      <mass value="${mass}" />
      <inertia ixx="${(1/12) * mass * (y*y + z*z)}" ixy="0.0" ixz="0.0"
               iyy="${(1/12) * mass * (x*x + z*z)}" iyz="0.0"
               izz="${(1/12) * mass * (x*x + y*y)}" />
    </inertial>
  </xacro:macro>

  <xacro:macro name="inertial_cylinder" params="mass length radius *origin">
    <inertial>
      <xacro:insert_block name="origin"/>
      <mass value="${mass}" />
      <inertia ixx="${(1/12) * mass * (3*radius*radius + length*length)}" ixy="0.0" ixz="0.0"
               iyy="${(1/12) * mass * (3*radius*radius + length*length)}" iyz="0.0"
               izz="${(1/2) * mass * (radius*radius)}" />
    </inertial>
  </xacro:macro>

  <xacro:property name="chassis_length" value="0.25"/>
  <xacro:property name="chassis_width"  value="0.2"/>
  <xacro:property name="chassis_height" value="0.14"/>

  <xacro:property name="wheel_radius"    value="0.021"/>  
  <xacro:property name="wheel_thickness" value="0.02"/>   
  <xacro:property name="wheel_mass"      value="0.05"/>
  <xacro:property name="wheel_separation" value="0.22"/>
  <xacro:property name="wheel_offset_y"   value="${wheel_separation/2}"/> 
  <xacro:property name="front_wheel_x"    value="0.07"/>
  <xacro:property name="back_wheel_x"     value="-0.07"/>
  <xacro:property name="wheel_center_z"   value="${-chassis_height/2 - wheel_radius}"/> 

  <material name="white">
    <color rgba="1 1 1 1" />
  </material>
  <material name="orange">
    <color rgba="1 0.3 0.1 1"/>
  </material>
  <material name="green">
    <color rgba="0 1 0 1"/>
  </material>
  <material name="black">
    <color rgba="0 0 0 1"/>
  </material>
  <material name="red">
    <color rgba="1 0 0 1"/>
  </material>

  <link name="base_link"/>

  <joint name="base_footprint_joint" type="fixed">
    <parent link="base_link"/>
    <child link="base_footprint"/>
    <origin xyz="0 0 -0.121" rpy="0 0 0"/>
  </joint>


  <link name="base_footprint"/>

  <joint name="chassis_joint" type="fixed">
    <parent link="base_link"/>
    <child link="chassis"/>
    <origin xyz="0 0 0"/>
  </joint>

  <link name="chassis">
    <visual>
      <origin xyz="0 0 0" rpy="0 0 0"/>
      <geometry>
        <box size="${chassis_length} ${chassis_width} ${chassis_height}"/>
      </geometry>
      <material name="green"/>
    </visual>

    <collision>
      <origin xyz="0 0 0"/>
      <geometry>
        <box size="${chassis_length} ${chassis_width} ${chassis_height}"/>
      </geometry>
    </collision>

    <xacro:inertial_box mass="1.0"
      x="${chassis_length}" y="${chassis_width}" z="${chassis_height}">
      <origin xyz="0 0 0"/>
    </xacro:inertial_box>
  </link>

  <gazebo reference="chassis">
    <material>Gazebo/Green</material>
  </gazebo>

  <joint name="front_left_wheel_joint" type="continuous">
    <parent link="base_link"/>
    <child link="front_left_wheel"/>
    <origin xyz="${front_wheel_x} ${wheel_offset_y} ${wheel_center_z}" rpy="-${pi/2} 0 0"/>
    <axis xyz="0 0 1"/>
  </joint>
  <link name="front_left_wheel">
    <visual>
      <origin xyz="0 0 0" rpy="0 0 0"/>
      <geometry>
        <cylinder radius="${wheel_radius}" length="${wheel_thickness}"/>
      </geometry>
      <material name="black"/>
    </visual>
    <collision>
      <origin xyz="0 0 0" rpy="0 0 0"/>
      <geometry>
        <cylinder radius="${wheel_radius}" length="${wheel_thickness}"/>
      </geometry>
    </collision>
    <xacro:inertial_cylinder mass="${wheel_mass}" length="${wheel_thickness}" radius="${wheel_radius}">
      <origin xyz="0 0 0" rpy="0 0 0"/>
    </xacro:inertial_cylinder>
  </link>
  <gazebo reference="front_left_wheel">
    <material>Gazebo/Black</material>
  </gazebo>

  <joint name="front_right_wheel_joint" type="continuous">
    <parent link="base_link"/>
    <child link="front_right_wheel"/>
    <origin xyz="${front_wheel_x} ${-wheel_offset_y} ${wheel_center_z}" rpy="${pi/2} 0 0"/>
    <axis xyz="0 0 -1"/>
  </joint>
  <link name="front_right_wheel">
    <visual>
      <origin xyz="0 0 0" rpy="0 0 0"/>
      <geometry>
        <cylinder radius="${wheel_radius}" length="${wheel_thickness}"/>
      </geometry>
      <material name="black"/>
    </visual>
    <collision>
      <origin xyz="0 0 0" rpy="0 0 0"/>
      <geometry>
        <cylinder radius="${wheel_radius}" length="${wheel_thickness}"/>
      </geometry>
    </collision>
    <xacro:inertial_cylinder mass="${wheel_mass}" length="${wheel_thickness}" radius="${wheel_radius}">
      <origin xyz="0 0 0" rpy="0 0 0"/>
    </xacro:inertial_cylinder>
  </link>
  <gazebo reference="front_right_wheel">
    <material>Gazebo/Black</material>
  </gazebo>

  <joint name="back_left_wheel_joint" type="continuous">
    <parent link="base_link"/>
    <child link="back_left_wheel"/>
    <origin xyz="${back_wheel_x} ${wheel_offset_y} ${wheel_center_z}" rpy="-${pi/2} 0 0"/>
    <axis xyz="0 0 1"/>
  </joint>
  <link name="back_left_wheel">
    <visual>
      <origin xyz="0 0 0" rpy="0 0 0"/>
      <geometry>
        <cylinder radius="${wheel_radius}" length="${wheel_thickness}"/>
      </geometry>
      <material name="black"/>
    </visual>
    <collision>
      <origin xyz="0 0 0" rpy="0 0 0"/>
      <geometry>
        <cylinder radius="${wheel_radius}" length="${wheel_thickness}"/>
      </geometry>
    </collision>
    <xacro:inertial_cylinder mass="${wheel_mass}" length="${wheel_thickness}" radius="${wheel_radius}">
      <origin xyz="0 0 0" rpy="0 0 0"/>
    </xacro:inertial_cylinder>
  </link>
  <gazebo reference="back_left_wheel">
    <material>Gazebo/Black</material>
  </gazebo>

  <joint name="back_right_wheel_joint" type="continuous">
    <parent link="base_link"/>
    <child link="back_right_wheel"/>
    <origin xyz="${back_wheel_x} ${-wheel_offset_y} ${wheel_center_z}" rpy="${pi/2} 0 0"/>
    <axis xyz="0 0 -1"/>
  </joint>
  <link name="back_right_wheel">
    <visual>
      <origin xyz="0 0 0" rpy="0 0 0"/>
      <geometry>
        <cylinder radius="${wheel_radius}" length="${wheel_thickness}"/>
      </geometry>
      <material name="black"/>
    </visual>
    <collision>
      <origin xyz="0 0 0" rpy="0 0 0"/>
      <geometry>
        <cylinder radius="${wheel_radius}" length="${wheel_thickness}"/>
      </geometry>
    </collision>
    <xacro:inertial_cylinder mass="${wheel_mass}" length="${wheel_thickness}" radius="${wheel_radius}">
      <origin xyz="0 0 0" rpy="0 0 0"/>
    </xacro:inertial_cylinder>
  </link>
  <gazebo reference="back_right_wheel">
    <material>Gazebo/Black</material>
  </gazebo>
  <gazebo>
    <plugin filename="libgazebo_ros_diff_drive.so" name="differential_drive_controller">
      <update_rate>100</update_rate>
      <ros>
        <namespace>/leader</namespace>
      </ros>
      <num_wheel_pairs>2</num_wheel_pairs>
      <left_joint>front_left_wheel_joint</left_joint>
      <right_joint>front_right_wheel_joint</right_joint>
      <left_joint>back_left_wheel_joint</left_joint>
      <right_joint>back_right_wheel_joint</right_joint>
      <wheel_separation>0.22</wheel_separation>
      <wheel_separation>0.22</wheel_separation>
      <wheel_diameter>0.021</wheel_diameter>
      <wheel_diameter>0.021</wheel_diameter>
      <max_wheel_torque>20</max_wheel_torque>
      <max_wheel_acceleration>1.0</max_wheel_acceleration>
      <publish_odom>true</publish_odom>
      <publish_odom_tf>true</publish_odom_tf>
      <publish_wheel_tf>true</publish_wheel_tf>
      <use_stamped_vel>false</use_stamped_vel>
      <odometry_frame>odom</odometry_frame>
      <robot_base_frame>leader/base_link</robot_base_frame>
    </plugin>
  </gazebo>

</robot>